Workbook

Sheet Sheet1
A1: Booked
A2: Complete
A3: Cancelled
A4: Need Assistance

Sheet Legend & Summary
E1: Dacorum Borough Council - Commercial Properties
D3: Booked / In Progress
D4: Cancelled survey requests
D5: Assistance required by Dacorum, Incorrect Telephone numbers etc.
D6: Complete surveys - Highlight once sent
E10: Management Surveys | F10: ASR1 Requests | G10: Spare Tab
D11: Number of requests | E11: =COUNTA('Management Survey'!F2:F100) -> 85 | F11: =COUNTA('ASR1 Requests'!G2:G85) -> 12 | G11: =COUNTA('Re-Inspections 26'!A2:A100) -> 51
D12: Complete | E12: =COUNTIF('Management Survey'!P2:P100,"complete") -> 0 | F12: =COUNTIF('ASR1 Requests'!Q2:Q85,"complete") -> 10 | G12: =COUNTA('Re-Inspections 26'!O2:O100) -> 0
D13: Outstanding | E13: =COUNTBLANK('Management Survey'!O2:O86) -> 0 | F13: =COUNTBLANK('ASR1 Requests'!Q2:Q13) -> 0 | G13: 0
D14: Booked | E14: =COUNTIF('Management Survey'!P2:P100,"booked") -> 0 | F14: =COUNTIF('ASR1 Requests'!Q2:Q85,"booked") -> 0 | G14: 0
D15: Cancelled | E15: =COUNTIF('Management Survey'!P2:P100,"cancelled") -> 0 | F15: =COUNTIF('ASR1 Requests'!Q2:Q85,"cancelled") -> 2 | G15: 0
D16: Need Assistance | E16: =COUNTIF('Management Survey'!P2:P100,"need assistance") -> 0 | F16: =COUNTIF('ASR1 Requests'!Q2:Q85,"need assistance") -> 0 | G16: 0

Sheet Management Survey
A1: Job Number | B1: Name | C1: Requestee | D1: Survey Type | E1: UPRN | F1: Address | G1: Post Code | H1: NOTES / MISSED APPTS | I1: Letter Sent | J1: Access issues | K1: Date received | L1: Date Surveyed | M1: Due Date | N1: Survey sent | O1: Status | P1: Re-inspections 2026
A2: G-17388 | C2: Richard Tattersall | D2: Management | F2: 48 High Street | G2: HP1 3AF | H2: Appoint Booked | L2: 45602 | N2: 45625 | O2: Complete
A3: G-17572 | C3: Richard Tattersall | D3: Management | F3: Adeyfield Community Centre | G3: HP2 4EW | H3: Appoint Booked | J3: Revisit required - Booked in with Julie Banks for the 7th Aug | L3: 45511 | N3: 45889 | O3: Complete | P3: =IFERROR(VLOOKUP(A3,#REF!, 2, FALSE), "")
A4: G-17887 | C4: Richard Tattersall | D4: Management | F4: Bellgate Shopping Centre 1-38 | G4: HP2 5SB | H4: Appoint Booked | J4: Not all areas available, revisit date DBC | L4: TBC | N4: 45776 | O4: Complete | P4: =IFERROR(VLOOKUP(A4,#REF!, 2, FALSE), "")
A5: G-17256 | C5: Richard Tattersall | D5: Management | F5: Bennetts End Community Centre | G5: HP3 9LZ | H5: Appoint Booked | L5: 45593 | N5: 45623 | O5: Complete | P5: =IFERROR(VLOOKUP(A5,#REF!, 2, FALSE), "")
A6: G-17855 | C6: Richard Tattersall | D6: Management | F6: Bennetsgate Shopping Centre 1-51 | G6: HP3 8EW | H6: Appoint Booked | L6: 45691 | N6: 45714 | O6: Complete | P6: =IFERROR(VLOOKUP(A6,#REF!, 2, FALSE), "")
A7: G-17364 | C7: Richard Tattersall | D7: Management | F7: Berkhampstead Civic Centre | G7: HP4 3HB | H7: Appoint Booked | L7: 45601 | N7: 45624 | O7: Complete | P7: =IFERROR(VLOOKUP(A7,#REF!, 2, FALSE), "")
A8: G-17421 | C8: Richard Tattersall | D8: Management | F8: Brickfields Ind Est 1-21 | G8: HP2 7QA | H8: Appoint Booked | L8: 45604 | N8: 45616 | O8: Complete | P8: =IFERROR(VLOOKUP(A8,#REF!, 2, FALSE), "")
A9: G-17763 | C9: Richard Tattersall | D9: Management | F9: Chaulden Adventure Playground | G9: HP1 2NX | H9: Appoint Booked | L9: 45631 | N9: 45643 | O9: Complete | P9: =IFERROR(VLOOKUP(A9,#REF!, 2, FALSE), "")
A10: G-17372 | C10: Richard Tattersall | D10: Management | F10: Chaulden Community Centre | G10: HP1 2HX | H10: Appoint Booked | L10: 45601 | N10: 45614 | O10: Complete | P10: =IFERROR(VLOOKUP(A10,#REF!, 2, FALSE), "")
A11: G-17886 | C11: Richard Tattersall | D11: Management | F11: Chaulden Shops | G11: HP1 2HX | H11: Appoint Booked | L11: 45692 | N11: 45707 | O11: Complete | P11: =IFERROR(VLOOKUP(A11,#REF!, 2, FALSE), "")
A12: G-17389 | C12: Richard Tattersall | D12: Management | F12: Cupid Green Depot (building A) | G12: HP2 7BA | H12: Appoint Booked | L12: 45603 | N12: 45615 | O12: Complete | P12: =IFERROR(VLOOKUP(A12,#REF!, 2, FALSE), "")
A13: G-17390 | C13: Richard Tattersall | D13: Management | F13: Cupid Green Depot (Buildings B&C) | G13: HP2 7BA | H13: Appoint Booked | L13: 45602 | N13: 45616 | O13: Complete | P13: =IFERROR(VLOOKUP(A13,#REF!, 2, FALSE), "")
A14: G-17325 | C14: Richard Tattersall | D14: Management | F14: Gadebridge Community Centre | G14: HP1 3LG | H14: Appoint Booked | L14: 45597 | N14: 45618 | O14: Complete | P14: =IFERROR(VLOOKUP(A14,#REF!, 2, FALSE), "")
A15: G-17327 | C15: Richard Tattersall | D15: Management | F15: Gadebridge Youth Centre | G15: HP1 3LF | H15: Appoint Booked | L15: 45597 | N15: 45615 | O15: Complete | P15: =IFERROR(VLOOKUP(A15,#REF!, 2, FALSE), "")
A16: G-17289 | C16: Richard Tattersall | D16: Management | F16: Grovehill Community Centre | G16: HP2 6BJ | H16: Appoint Booked | L16: 45594 | N16: 45606 | O16: Complete | P16: =IFERROR(VLOOKUP(A16,#REF!, 2, FALSE), "")
A17: G-17643 | C17: Richard Tattersall | D17: Management | F17: Heath Lane cemetery Chapel | G17: HP1 1TS | H17: Appoint Booked | L17: 45632 | N17: 45646 | O17: Complete | P17: =IFERROR(VLOOKUP(A17,#REF!, 2, FALSE), "")
A18: G-17644 | C18: Richard Tattersall | D18: Management | F18: Heath Lane cemetery Lodge | G18: HP1 1TS | H18: Appoint rebooked with Maria for the 3rd April | J18: 6/12 Tenant of Lodge wouldn't allow access, rebook | L18: 45750 | N18: 45758 | O18: Complete | P18: =IFERROR(VLOOKUP(A18,#REF!, 2, FALSE), "")
A19: G-19396 | C19: Richard Tattersall | D19: Management | F19: Hemel Hempstead Bowls Club | G19: HP1 1HR | J19: No answer to various calls, emails. Chris Conley, put me in touch with Micheal Darke at the club who has booked this in for 9.30am on the 11th April | L19: 45758 | O19: Complete | P19: =IFERROR(VLOOKUP(A19,#REF!, 2, FALSE), "")
A20: G-17444 | C20: Richard Tattersall | D20: Management | F20: High Street Green Sports Pavillion | G20: HP2 7AR | H20: Appoint Booked | L20: 45604 | N20: 45628 | O20: Complete | P20: =IFERROR(VLOOKUP(A20,#REF!, 2, FALSE), "")
A21: G-17291 | C21: Richard Tattersall | D21: Management | F21: Highfield Community Centre | G21: HP2 5SB | H21: Appoint Booked | J21: Bar No access - Awaiting date and time we can access this area | L21: 45792 | N21: 45793 | O21: Complete | P21: =IFERROR(VLOOKUP(A21,#REF!, 2, FALSE), "")
A22: G-17885 | C22: Richard Tattersall | D22: Management | F22: Hobbs Hill Road Shops | G22: HP3 9QG | H22: Appoint Booked | L22: 45685 | N22: 45695 | O22: Complete | P22: =IFERROR(VLOOKUP(A22,#REF!, 2, FALSE), "")
A23: G-19256 | C23: Richard Tattersall | D23: Management | F23: Kingshill Cemetery Lodge | G23: HP4 3UG | H23: Appoint Booked | L23: 45750 | N23: 45758 | O23: Complete | P23: =IFERROR(VLOOKUP(A23,#REF!, 2, FALSE), "")
A24: G-19257 | C24: Richard Tattersall | D24: Management | F24: Kingshill Cemetery Workshop, Welfare Area & toilets | G24: HP4 3UG | H24: Appoint Booked | L24: 45750 | N24: 45758 | O24: Complete | P24: =IFERROR(VLOOKUP(A24,#REF!, 2, FALSE), "")
A25: G-17445 | C25: Richard Tattersall | D25: Management | F25: Leverstock Green Sports pavilion | G25: HP3 8QG | H25: Appoint Booked | L25: 45607 | N25: 45990 | O25: Complete | P25: =IFERROR(VLOOKUP(A25,#REF!, 2, FALSE), "")
A26: G-18507 | C26: Richard Tattersall | D26: Management | F26: Leverstock Green Village Centre Shops | G26: HP3 8QG | H26: Appoint Booked | L26: 45693 | N26: 45707 | O26: Complete | P26: =IFERROR(VLOOKUP(A26,#REF!, 2, FALSE), "")
A27: G-17318 | C27: Richard Tattersall | D27: Management | F27: Leverstock Green Village Hall | G27: HP3 8QG | H27: Appoint Booked | J27: No access to library - Book revisit for a Thursday | L27: TBC | N27: 45775 | O27: Complete | P27: =IFERROR(VLOOKUP(A27,#REF!, 2, FALSE), "")
A28: G-17446 | C28: Richard Tattersall | D28: Management | F28: Nash Mills Recreation Area Shower & Toilet Facilities | G28: HP3 9TE | H28: Appoint Booked | L28: 45628 | N28: 45642 | O28: Complete | P28: =IFERROR(VLOOKUP(A28,#REF!, 2, FALSE), "")
A29: G-18148 | C29: Richard Tattersall | D29: Management | F29: Old Town Hall | G29: HP1 3AE | H29: Appoint Booked | L29: 45698 | N29: 45706 | O29: Complete | P29: =IFERROR(VLOOKUP(A29,#REF!, 2, FALSE), "")
A30: G-19397 | C30: Richard Tattersall | D30: Management | F30: Old Town Public Convenience | G30: HP1 3AE | H30: Appoint Booked | J30: Tony Moore to have keys avaialable for us to collect from the Bowls Club in the morning | L30: 45758 | N30: 45776 | O30: Complete | P30: =IFERROR(VLOOKUP(A30,#REF!, 2, FALSE), "")
A31: G-18146 | C31: Richard Tattersall | D31: Management | F31: Queens Square Shopping Centre | G31: HP2 4ES | H31: Appoint Booked | L31: 45699 | N31: 45708 | O31: Complete | P31: =IFERROR(VLOOKUP(A31,#REF!, 2, FALSE), "")
A32: G-18147 | C32: Richard Tattersall | D32: Management | F32: Stoneycroft Shopping Centre | G32: HP1 2QF | H32: Appoint Booked | L32: 45672 | N32: 45692 | O32: Complete | P32: =IFERROR(VLOOKUP(A32,#REF!, 2, FALSE), "")
A33: G-18292 | C33: Richard Tattersall | D33: Management | F33: The Bury registry Office | G33: HP1 1HR | H33: Appoint Booked | L33: 45700 | N33: 45707 | O33: Complete | P33: =IFERROR(VLOOKUP(A33,#REF!, 2, FALSE), "")
A34: G-17366 | C34: Richard Tattersall | D34: Management | F34: The Centre in the Park | G34: HP1 3AE | H34: Appoint Booked | L34: 45600 | N34: 45631 | O34: Complete | P34: =IFERROR(VLOOKUP(A34,#REF!, 2, FALSE), "")
A35: G-18293 | C35: Richard Tattersall | D35: Management | F35: The Counting House | G35: HP23 5TE | H35: Appoint Booked | L35: 45701 | N35: 45715 | O35: Complete | P35: =IFERROR(VLOOKUP(A35,#REF!, 2, FALSE), "")
A36: G-18508 | C36: Richard Tattersall | D36: Management | F36: The Denes Shopping Centre | G36: HP3 8AP | H36: Appoint Booked | L36: 45695 | N36: 45719 | O36: Complete | P36: =IFERROR(VLOOKUP(A36,#REF!, 2, FALSE), "")
A37: G-19398 | C37: Richard Tattersall | D37: Management | F37: The Forge Car Park Public Convenience | G37: HP23 5SH | H37: Appoint Booked | J37: Keysafe for access (1972) | L37: 45758 | N37: 45776 | O37: Complete | P37: =IFERROR(VLOOKUP(A37,#REF!, 2, FALSE), "")
A38: G-18471 | C38: Richard Tattersall | D38: Management | F38: The Gables ( Relate) | G38: HP2 5HL | H38: Appoint Booked | L38: 45694 | N38: 45706 | O38: Complete | P38: =IFERROR(VLOOKUP(A38,#REF!, 2, FALSE), "")
A39: G-17854 | C39: Richard Tattersall | D39: Management | F39: The Heights Shopping Centre | G39: HP2 5NX | H39: Appoint Booked | L39: 45637 | N39: 45664 | O39: Complete | P39: =IFERROR(VLOOKUP(A39,#REF!, 2, FALSE), "")
A40: G-17365 | C40: Richard Tattersall | D40: Management | F40: Tring community Centre | G40: HP23 5EP | H40: Appoint Booked | L40: 45679 | N40: 45691 | O40: Complete | P40: =IFERROR(VLOOKUP(A40,#REF!, 2, FALSE), "")
...

Sheet ASR1 Requests
A1: Job Number | B1: Name | C1: Requestee | D1: Building Type | E1: Survey Type | F1: UPRN | G1: Address | H1: Post Code | I1: Contact Number | J1: NOTES / MISSED APPTS | K1: Letter Sent | L1: Access Issues | M1: Date Received | N1: Date Surveyed | O1: Due Date | P1: Survey Sent | Q1: Status
A2: G-17422 | C2: Richard Tattersall | D2: Commercial | E2: Management | G2: Unit 10 Brickfield | H2: HP2 7QA | M2: 45594 | N2: 45604 | P2: 45616 | Q2: Complete
A3: G-17792 | C3: Tony Moore | D3: Commercial | E3: Refurbishment | G3: 128-130 Bennetsgate | H3: HP3 8DZ | M3: 45630 | N3: 45631 | P3: 45636 | Q3: Complete
A4: G17952 | C4: Richard Tattersall | D4: Commercial | E4: Management | G4: Grovehill Youth Centre | H4: HP2 6BH | M4: 45643 | N4: 45649 | P4: 45307 | Q4: Complete
C5: Jim Mitchell | D5: Commercial | E5: Refurbishment | G5: House that jack built - Nursery | H5: HP3 8EW | J5: Spoke to Jim, he said to cancel request as the works have already been carried out | Q5: Cancelled
A6: G-18204 | C6: Horace White | D6: Commercial | E6: Management | G6: 1-2 Hammer Lane | H6: HP2 4EU | M6: 45673 | N6: 45677 | P6: 45679 | Q6: Complete
C7: Richard Tattersall | D7: Commercial | E7: Refurbishment | G7: 14 Appsley Ind Est | H7: HP3 9XH | J7: Called to book in survey, Jim Mitchell advised that a survey had already been carried out and that this is not now required | M7: 45666 | Q7: Cancelled
A8: G-18816 | C8: Tony Moore | D8: Commercial | E8: Refurbishment | G8: 3 Queensway | H8: HP1 1LS | M8: 45716 | N8: 45719 | P8: 45722 | Q8: Complete
A9: G-19978 | C9: Jim Mitchell | D9: Commercial | E9: Refurbishment | G9: Unit 8 Appsley | H9: HP3 9XH | M9: 45786 | N9: 45790 | P9: 45793 | Q9: Complete
A10: G-19979 | C10: Tony Moore | D10: Commercial | E10: Management | G10: 52 Old Town | H10: HP1 3AF | M10: 45786 | N10: 45791 | P10: 45796 | Q10: Complete
A11: G-19980 | C11: Tony Moore | D11: Commercial | E11: Management | G11: 100 Old Town | H11: HP1 3AQ | M11: 45786 | N11: 45790 | P11: 45793 | Q11: Complete
A12: G-18293 Iss 3 | C12: Tony Moore | D12: Commercial | E12: Refurbishment | G12: The Counting House | H12: HP1 1HH | J12: Works being undertaken in the basement that was previously innaccesible, Tony asked us to attend to meet Orion on site to run through works and survey the area | M12: 45896 | N12: 45897 | P12: 45901 | Q12: Complete
A13: G-23025 | C13: Richard Tattersall | D13: Commercial | E13: Refurbishment | G13: Little Hay Golf Complex | H13: HP3 0DT | J13: Left Message & Sent email to Gearge Reid for access | M13: 45954 | N13: 45964 | P13: 45973 | Q13: Complete

Sheet Spare
A1: Job Number | B1: Name | C1: Requestee | D1: Work Type | E1: Priority of works | F1: UPRN | G1: Address | H1: Post Code | I1: Contact Number | J1: NOTES / MISSED APPTS | K1: Letter Sent | L1: Access Issues | M1: Date Received | N1: Date Surveyed | O1: Due Date | P1: Survey Sent | Q1: Status
Q2: =IFERROR(VLOOKUP(A2,#REF!, 2, FALSE), "")

Sheet Re-Inspections 26
A1: Job Number | B1: Name | C1: Requestee | D1: Work Type | E1: UPRN | F1: Address | G1: Post Code | H1: NOTES / MISSED APPTS | I1: Letter Sent | J1: Access Issues | K1: Date Received | L1: Date Surveyed | M1: Due Date | N1: Survey Sent | O1: Status
A2: G-17256 | C2: Richard Tattersall | D2: Management | F2: Bennetts End Community Centre | G2: HP3 9LZ | H2: Appoint Booked | K2: 45623
A3: G-17289 | C3: Richard Tattersall | D3: Management | F3: Grovehill Community Centre | G3: HP2 6BJ | H3: Appoint Booked | K3: 45606
A4: G-17291 | C4: Richard Tattersall | D4: Management | F4: Highfield Community Centre | G4: HP2 5SB | H4: Appoint Booked | J4: Bar No access - Awaiting date and time we can access this area | K4: 45797
A5: G-17318 | C5: Richard Tattersall | D5: Management | F5: Leverstock Green Village Hall | G5: HP3 8QG | H5: Appoint Booked | J5: No access to library - Book revisit for a Thursday | K5: 45772
A6: G-17325 | C6: Richard Tattersall | D6: Management | F6: Gadebridge Community Centre | G6: HP1 3LG | H6: Appoint Booked | K6: 45623
A7: G-17327 | C7: Richard Tattersall | D7: Management | F7: Gadebridge Youth Centre | G7: HP1 3LF | H7: Appoint Booked | K7: 45615
A8: G-17329 | C8: Richard Tattersall | D8: Management | F8: Woodhall farm Community Centre | G8: HP2 7JX | H8: Appoint Booked | K8: 45618
A9: G-17364 | C9: Richard Tattersall | D9: Management | F9: Berkhampstead Civic Centre | G9: HP4 3HB | H9: Appoint Booked | K9: 45624
A10: G-17365 | C10: Richard Tattersall | D10: Management | F10: Tring community Centre | G10: HP23 5EP | H10: Appoint Booked | K10: 45694
A11: G-17366 | C11: Richard Tattersall | D11: Management | F11: The Centre in the Park | G11: HP1 3AE | H11: Appoint Booked | K11: 45633
A12: G-17372 | C12: Richard Tattersall | D12: Management | F12: Chaulden Community Centre | G12: HP1 2HX | H12: Appoint Booked | K12: 45636
A13: G-17389 | C13: Richard Tattersall | D13: Management | F13: Cupid Green Depot (building A) | G13: HP2 7BA | H13: Appoint Booked | K13: 45615
A14: G-17390 | C14: Richard Tattersall | D14: Management | F14: Cupid Green Depot (Buildings B&C) | G14: HP2 7BA | H14: Appoint Booked | K14: 45616
A15: G-17421 | C15: Richard Tattersall | D15: Management | F15: Brickfields Ind Est 1-21 | G15: HP2 7QA | H15: Appoint Booked | K15: 45616
A16: G-17444 | C16: Richard Tattersall | D16: Management | F16: High Street Green Sports Pavillion | G16: HP2 7AR | H16: Appoint Booked | K16: 45642
A17: G-17445 | C17: Richard Tattersall | D17: Management | F17: Leverstock Green Sports pavilion | G17: HP3 8QG | H17: Appoint Booked | K17: 45625
A18: G-17446 | C18: Richard Tattersall | D18: Management | F18: Nash Mills Recreation Area Shower & Toilet Facilities | G18: HP3 9TE | H18: Appoint Booked | K18: 45645
A19: G-17572 | C19: Richard Tattersall | D19: Management | F19: Adeyfield Community Centre | G19: HP2 4EW | H19: Appoint Booked | J19: Revisit required - Booked in with Julie Banks for the 7th Aug | K19: 45889
A20: G-17640 | C20: Richard Tattersall | D20: Management | F20: Tringford depot | G20: HP23 4JL | H20: Appoint Booked | K20: 45707
A21: G-17643 | C21: Richard Tattersall | D21: Management | F21: Heath Lane cemetery Chapel | G21: HP1 1TS | H21: Appoint Booked | K21: 45646
A22: G-17644 | C22: Richard Tattersall | D22: Management | F22: Heath Lane cemetery Lodge | G22: HP1 1TS | H22: Appoint rebooked with Maria for the 3rd April | J22: 6/12 Tenant of Lodge wouldn't allow access, rebook | K22: 45647
A23: G-17661 | C23: Richard Tattersall | D23: Management | F23: Warners End community Centre | G23: HP1 3QG | H23: Appoint Booked | K23: 45679
A24: G-17763 | C24: Richard Tattersall | D24: Management | F24: Chaulden Adventure Playground | G24: HP1 2NX | H24: Appoint Booked | K24: 45646
A25: G-17854 | C25: Richard Tattersall | D25: Management | F25: The Heights Shopping Centre | G25: HP2 5NX | H25: Appoint Booked | K25: 45664
A26: G-17855 | C26: Richard Tattersall | D26: Management | F26: Bennetsgate Shopping Centre 1-51 | G26: HP3 8EW | H26: Appoint Booked | K26: 45714
A27: G-17885 | C27: Richard Tattersall | D27: Management | F27: Hobbs Hill Road Shops | G27: HP3 9QG | H27: Appoint Booked | K27: 45670
A28: G-17886 | C28: Richard Tattersall | D28: Management | F28: Chaulden Shops | G28: HP1 2HX | H28: Appoint Booked | K28: 45707
A29: G-17887 | C29: Richard Tattersall | D29: Management | F29: Bellgate Shopping Centre 1-38 | G29: HP2 5SB | H29: Appoint Booked | J29: Not all areas available, revisit date DBC | K29: 45776
A30: G-18146 | C30: Richard Tattersall | D30: Management | F30: Queens Square Shopping Centre | G30: HP2 4ES | H30: Appoint Booked | K30: 45707
A31: G-18147 | C31: Richard Tattersall | D31: Management | F31: Stoneycroft Shopping Centre | G31: HP1 2QF | H31: Appoint Booked | K31: 45692
A32: G-18148 | C32: Richard Tattersall | D32: Management | F32: Old Town Hall | G32: HP1 3AE | H32: Appoint Booked | K32: 45706
A33: G-18292 | C33: Richard Tattersall | D33: Management | F33: The Bury registry Office | G33: HP1 1HR | H33: Appoint Booked | K33: 45707
A34: G-18293 | C34: Richard Tattersall | D34: Management | F34: The Counting House | G34: HP23 5TE | H34: Appoint Booked | K34: 45901
A35: G-18471 | C35: Richard Tattersall | D35: Management | F35: The Gables ( Relate) | G35: HP2 5HL | H35: Appoint Booked | K35: 45706
A36: G-18507 | C36: Richard Tattersall | D36: Management | F36: Leverstock Green Village Centre Shops | G36: HP3 8QG | H36: Appoint Booked | K36: 45707
A37: G-18508 | C37: Richard Tattersall | D37: Management | F37: The Denes Shopping Centre | G37: HP3 8AP | H37: Appoint Booked | K37: 45722
A38: G-19211 | C38: Richard Tattersall | D38: Management | F38: Woodwells Cemetery Office, toilets & Workshop | G38: HP2 7LF | H38: Appoint Booked | K38: 45757
A39: G-19212 | C39: Richard Tattersall | D39: Management | F39: Woodwells Cemetery Lodge | G39: HP2 7LF | H39: Appoint Booked | K39: 45756
A40: G-19257 | C40: Richard Tattersall | D40: Management | F40: Kingshill Cemetery Workshop, Welfare Area & toilets | G40: HP4 3UG | H40: Appoint Booked | K40: 45757
...
